Log file created at: 2024/09/15 21:35:41
Running on machine: hqm-HP-ZBook-Ubuntu-24-04
Running duration (h:mm:ss): 0:00:00
Log line format: [IWEF]yyyymmdd hh:mm:ss.uuuuuu threadid file:line] msg
W20240915 21:35:41.795142 51767 core-base.cpp:20] Waiting for the first frame frome video.
E20240915 21:35:43.854333 51767 viewer-video.cpp:115] Failed to run python script, please check web log.
E20240915 21:35:43.855127 51767 viewer-video.cpp:116] LOG:
E20240915 21:35:43.855185 51767 viewer-video.cpp:117] [2024-09-15 21:35:42 +0800] [51789] [INFO] Starting gunicorn 23.0.0
[2024-09-15 21:35:42 +0800] [51789] [INFO] Listening at: http://0.0.0.0:9003 (51789)
[2024-09-15 21:35:42 +0800] [51789] [INFO] Using worker: sync
[2024-09-15 21:35:42 +0800] [51836] [INFO] Booting worker with pid: 51836
[2024-09-15 21:35:43 +0800] [51836] [ERROR] Exception in worker process
Traceback (most recent call last):
  File "/home/zichun/.pyenv/versions/3.10.15/envs/TensorRT8/lib/python3.10/site-packages/gunicorn/arbiter.py", line 608, in spawn_worker
    worker.init_process()
  File "/home/zichun/.pyenv/versions/3.10.15/envs/TensorRT8/lib/python3.10/site-packages/gunicorn/workers/base.py", line 135, in init_process
    self.load_wsgi()
  File "/home/zichun/.pyenv/versions/3.10.15/envs/TensorRT8/lib/python3.10/site-packages/gunicorn/workers/base.py", line 147, in load_wsgi
    self.wsgi = self.app.wsgi()
  File "/home/zichun/.pyenv/versions/3.10.15/envs/TensorRT8/lib/python3.10/site-packages/gunicorn/app/base.py", line 66, in wsgi
    self.callable = self.load()
  File "/home/zichun/.pyenv/versions/3.10.15/envs/TensorRT8/lib/python3.10/site-packages/gunicorn/app/wsgiapp.py", line 57, in load
    return self.load_wsgiapp()
  File "/home/zichun/.pyenv/versions/3.10.15/envs/TensorRT8/lib/python3.10/site-packages/gunicorn/app/wsgiapp.py", line 47, in load_wsgiapp
    return util.import_app(self.app_uri)
  File "/home/zichun/.pyenv/versions/3.10.15/envs/TensorRT8/lib/python3.10/site-packages/gunicorn/util.py", line 370, in import_app
    mod = importlib.import_module(module)
  File "/home/zichun/.pyenv/versions/3.10.15/lib/python3.10/importlib/__init__.py", line 126, in import_module
    return _bootstrap._gcd_import(name[level:], package, level)
  File "<frozen importlib._bootstrap>", line 1050, in _gcd_import
  File "<frozen importlib._bootstrap>", line 1027, in _find_and_load
  File "<frozen importlib._bootstrap>", line 1006, in _find_and_load_unlocked
  File "<frozen importlib._bootstrap>", line 688, in _load_unlocked
  File "<frozen importlib._bootstrap_external>", line 883, in exec_module
  File "<frozen importlib._bootstrap>", line 241, in _call_with_frames_removed
  File "/home/zichun/1_SHU_Programming/SRM_training/rm-out/modules/viewer/video.py", line 4, in <module>
    from flask import Flask, render_template, request, jsonify, Response
ModuleNotFoundError: No module named 'flask'
[2024-09-15 21:35:43 +0800] [51836] [INFO] Worker exiting (pid: 51836)
[2024-09-15 21:35:43 +0800] [51789] [ERROR] Worker (pid:51836) exited with code 3
[2024-09-15 21:35:43 +0800] [51789] [ERROR] Shutting down: Master
[2024-09-15 21:35:43 +0800] [51789] [ERROR] Reason: Worker failed to boot.
E20240915 21:35:43.855418 51767 autoaim-base.cpp:17] Failed to initialize viewer.
E20240915 21:35:45.372313 51767 cuda-help.h:38] 6: The engine plan file is generated on an incompatible device, expecting compute 8.9 got compute 8.6, please rebuild.
E20240915 21:35:45.436902 51767 cuda-help.h:38] 2: [engine.cpp::deserializeEngine::951] Error Code 2: Internal Error (Assertion engine->deserialize(start, size, allocator, runtime) failed. )
E20240915 21:35:45.437881 51767 tensorrt.cpp:66] Build CUDA engine failed.
